Workbook

Sheet GW_mostrecent_May3_GIS
A1: GIS_name | B1: Sample_Date | C1: ID | D1: Map_Key | E1: ID no PII | F1: PWS_ID | G1: Type | H1: Latitude | I1: Longitude | J1: PFBS | K1: PFHpA | L1: PFHxS | M1: PFNA | N1: PFOA | O1: PFOS
A2: Wigwam Well CR #1 | B2: 39595 | C2: Wigwam Well CR #1 2008-05-27 | D2: 131 | E2: FSW-131 | F2: =VLOOKUP(A2,Type!$A$1:$C$132,3,0) -> CO0121470 | G2: =VLOOKUP(A2,Type!$A$1:$B$132,2,0) -> PWS and Other | H2: 38.541917 | I2: -104.64063 | J2: 27 | K2: 7.5 | L2: 50 | M2: 0 | N2: 25 | O2: 18
A3: CO. Centre Metro district | B3: 42548 | C3: CO. Centre Metro district 2016-06-27 | D3: 88 | E3: FSW-88 | F3: =VLOOKUP(A3,Type!$A$1:$C$132,3,0) -> CO0121140 | G3: =VLOOKUP(A3,Type!$A$1:$B$132,2,0) -> PWS and Other | H3: 38.768417 | I3: -104.64929 | J3: 0 | K3: 0 | L3: 0 | M3: 0 | N3: 0 | O3: 0
A4: Widefield Jhw5R Well | B4: 41778 | C4: Widefield Jhw5R Well 2014-05-19 | D4: 90 | E4: FSW-90 | F4: =VLOOKUP(A4,Type!$A$1:$C$132,3,0) -> CO0121900 | G4: =VLOOKUP(A4,Type!$A$1:$B$132,2,0) -> PWS and Other | H4: 38.730278 | I4: -104.65111 | J4: 0 | K4: 0 | L4: 0 | M4: 0 | N4: 0 | O4: 0
A5: Widefield Well JHW2 | B5: 42536 | C5: Widefield Well JHW2 2016-06-15 | D5: 130 | E5: FSW-130 | F5: =VLOOKUP(A5,Type!$A$1:$C$132,3,0) -> CO0121900 | G5: =VLOOKUP(A5,Type!$A$1:$B$132,2,0) -> PWS and Other | H5: 38.7298 | I5: -104.65357 | N5: 4.7 | O5: 2.9
A6: private well 9035 Bonnie Cap | B6: 42695 | C6: private well 9035 Bonnie Cap 2016-11-21 | D6: 122 | E6: FSW-122 | G6: =VLOOKUP(A6,Type!$A$1:$B$132,2,0) -> Private Well | H6: 38.710278 | I6: -104.66056 | J6: 0 | K6: 0 | L6: 40 | M6: 0 | N6: 29 | O6: 10
A7: private well 8085 S. Marksheffel Rd. | B7: 42580 | C7: private well 8085 S. Marksheffel Rd. 2016-07-29 | D7: 95 | E7: FSW-95 | G7: =VLOOKUP(A7,Type!$A$1:$B$132,2,0) -> Private Well | H7: 38.714635 | I7: -104.66105 | J7: 0 | K7: 1.8 | L7: 30 | M7: 0 | N7: 0 | O7: 0
A8: private well 16990 Old Pueblo Rd #1 | B8: 42464 | C8: private well 16990 Old Pueblo Rd #1 2016-04-04 | D8: 26 | E8: FSW-26 | G8: =VLOOKUP(A8,Type!$A$1:$B$132,2,0) -> Private Well | H8: 38.588448 | I8: -104.66316 | J8: 0 | K8: 13 | L8: 93 | M8: 0 | N8: 35 | O8: 55
A9: private well 8225 S. Marksheffel Rd. | B9: 42580 | C9: private well 8225 S. Marksheffel Rd. 2016-07-29 | D9: 96 | E9: FSW-96 | G9: =VLOOKUP(A9,Type!$A$1:$B$132,2,0) -> Private Well | H9: 38.712832 | I9: -104.66321 | J9: 0 | K9: 2.4 | L9: 36 | M9: 0 | N9: 0 | O9: 0
A10: private well 16990 Old Pueblo Rd #2 | B10: 42464 | C10: private well 16990 Old Pueblo Rd #2 2016-04-04 | D10: 27 | E10: FSW-27 | G10: =VLOOKUP(A10,Type!$A$1:$B$132,2,0) -> Private Well | H10: 38.589011 | I10: -104.66578 | J10: 0 | K10: 14 | L10: 97 | M10: 0 | N10: 40 | O10: 46
A11: private well 8790 Birdsall Rd. | B11: 42619 | C11: private well 8790 Birdsall Rd. 2016-09-06 | D11: 114 | E11: FSW-114 | G11: =VLOOKUP(A11,Type!$A$1:$B$132,2,0) -> Private Well | H11: 38.626111 | I11: -104.66639 | J11: 26 | K11: 6.4 | L11: 36 | M11: 0 | N11: 14 | O11: 0
A12: private well 13421 Moonshadow Rd. | B12: 42619 | C12: private well 13421 Moonshadow Rd. 2016-09-06 | D12: 110 | E12: FSW-110 | G12: =VLOOKUP(A12,Type!$A$1:$B$132,2,0) -> Private Well | H12: 38.630555 | I12: -104.66805 | J12: 19 | K12: 6.4 | L12: 26 | M12: 0 | N12: 12 | O12: 0
A13: private well 16880 Old Pueblo | B13: 42460 | C13: private well 16880 Old Pueblo 2016-03-31 | D13: 25 | E13: FSW-25 | G13: =VLOOKUP(A13,Type!$A$1:$B$132,2,0) -> Private Well | H13: 38.5969 | I13: -104.6693 | J13: 0 | K13: 13 | L13: 82 | M13: 0 | N13: 36 | O13: 66
A14: private well 14910 Old Pueblo Rd | B14: 42548 | C14: private well 14910 Old Pueblo Rd 2016-06-27 | D14: 79 | E14: FSW-79 | G14: =VLOOKUP(A14,Type!$A$1:$B$132,2,0) -> Private Well | H14: 38.615811 | I14: -104.67348 | J14: 0 | K14: 8.7 | L14: 25 | M14: 0 | N14: 16 | O14: 31
A15: private well 9110 Link Rd. | B15: 42579 | C15: private well 9110 Link Rd. 2016-07-28 | D15: 101 | E15: FSW-101 | G15: =VLOOKUP(A15,Type!$A$1:$B$132,2,0) -> Private Well | H15: 38.700009 | I15: -104.67379 | J15: 0 | K15: 0 | L15: 33 | M15: 0 | N15: 0 | O15: 0
A16: private well 8570 Link Rd | B16: 42695 | C16: private well 8570 Link Rd 2016-11-21 | D16: 119 | E16: FSW-119 | G16: =VLOOKUP(A16,Type!$A$1:$B$132,2,0) -> Private Well | H16: 38.707222 | I16: -104.67417 | J16: 21 | K16: 3.7 | L16: 56 | M16: 0 | N16: 3.7 | O16: 0
A17: private well 14790 Old Pueblo Rd. | B17: 42619 | C17: private well 14790 Old Pueblo Rd. 2016-09-06 | D17: 112 | E17: FSW-112 | G17: =VLOOKUP(A17,Type!$A$1:$B$132,2,0) -> Private Well | H17: 38.618333 | I17: -104.67444 | J17: 26 | K17: 4.4 | L17: 24 | M17: 0 | N17: 8 | O17: 0
... A39: private well 12460 Old Pueblo Rd | B39: 42695 | C39: private well 12460 Old Pueblo Rd 2016-11-21 | D39: 118 | E39: FSW-118 | G39: =VLOOKUP(A39,Type!$A$1:$B$132,2,0) -> Private Well | H39: 38.65 | I39: -104.68889 | J39: 33 | K39: 9 | L39: 70 | M39: 0 | N39: 44 | O39: 36
A40: Fountain Faith Fellowship | B40: 42548 | C40: Fountain Faith Fellowship 2016-06-27 | D40: 77 | E40: FSW-77 | F40: =VLOOKUP(A40,Type!$A$1:$C$132,3,0) -> CO0121300 | G40: =VLOOKUP(A40,Type!$A$1:$B$132,2,0) -> PWS and Other | H40: 38.659137 | I40: -104.69044 | J40: 0 | K40: 3.8 | L40: 10 | M40: 0 | N40: 9.1 | O40: 0
A41: private well 12425 Old Pueblo | B41: 42460 | C41: private well 12425 Old Pueblo 2016-03-31 | D41: 23 | E41: FSW-23 | G41: =VLOOKUP(A41,Type!$A$1:$B$132,2,0) -> Private Well | H41: 38.6561 | I41: -104.6914 | J41: 0 | K41: 22 | L41: 86 | M41: 0 | N41: 45 | O41: 41
A42: private well 808 Pond Terrace | B42: 42695 | C42: private well 808 Pond Terrace 2016-11-21 | D42: 123 | E42: FSW-123 | G42: =VLOOKUP(A42,Type!$A$1:$B$132,2,0) -> Private Well | H42: 38.691389 | I42: -104.69722 | J42: 32 | K42: 5 | L42: 60 | M42: 0 | N42: 21 | O42: 32
A43: private well 900 Pond Terrace | B43: 42695 | C43: private well 900 Pond Terrace 2016-11-21 | D43: 124 | E43: FSW-124 | G43: =VLOOKUP(A43,Type!$A$1:$B$132,2,0) -> Private Well | H43: 38.688611 | I43: -104.6975 | J43: 16 | K43: 2.3 | L43: 25 | M43: 0 | N43: 8.5 | O43: 14
A44: private well 1205 Fountain Mesa | B44: 42460 | C44: private well 1205 Fountain Mesa 2016-03-31 | D44: 19 | E44: FSW-19 | G44: =VLOOKUP(A44,Type!$A$1:$B$132,2,0) -> Private Well | H44: 38.6981 | I44: -104.6981 | J44: 0 | K44: 12 | L44: 81 | M44: 0 | N44: 30 | O44: 67
A45: private well 952 Lake Ave. | B45: 42579 | C45: private well 952 Lake Ave. 2016-07-28 | D45: 34 | E45: FSW-34 | G45: =VLOOKUP(A45,Type!$A$1:$B$132,2,0) -> Private Well | H45: 38.693954 | I45: -104.69835 | J45: 23 | K45: 10 | L45: 54 | M45: 0 | N45: 27 | O45: 62
A46: Fountain Well No 3 Shop Well | C46: Fountain Well No 3 Shop Well NA | D46: 5 | E46: FSW-5 | F46: =VLOOKUP(A46,Type!$A$1:$C$132,3,0) -> CO0121300 | G46: =VLOOKUP(A46,Type!$A$1:$B$132,2,0) -> PWS and Other | H46: 38.681945 | I46: -104.69972 | J46: 0 | K46: 0 | L46: 50 | M46: 0 | N46: 27 | O46: 50
A47: private well 300 Georgia Lee Lane | B47: 42580 | C47: private well 300 Georgia Lee Lane 2016-07-29 | D47: 99 | E47: FSW-99 | G47: =VLOOKUP(A47,Type!$A$1:$B$132,2,0) -> Private Well | H47: 38.705221 | I47: -104.70208 | J47: 19 | K47: 8.3 | L47: 31 | M47: 4.6 | N47: 23 | O47: 52
A48: Fountain Well No 2 South Park Well | C48: Fountain Well No 2 South Park Well NA | D48: 4 | E48: FSW-4 | F48: =VLOOKUP(A48,Type!$A$1:$C$132,3,0) -> CO0121300 | G48: =VLOOKUP(A48,Type!$A$1:$B$132,2,0) -> PWS and Other | H48: 38.685555 | I48: -104.70278 | J48: 0 | K48: 10 | L48: 54 | M48: 0 | N48: 32 | O48: 49
A49: Fountain Well No 1 North Park Well | B49: 41472 | C49: Fountain Well No 1 North Park Well 2013-07-17 | D49: 93 | E49: FSW-93 | F49: =VLOOKUP(A49,Type!$A$1:$C$132,3,0) -> CO0121300 | G49: =VLOOKUP(A49,Type!$A$1:$B$132,2,0) -> PWS and Other | H49: 38.686679 | I49: -104.70371 | J49: 0 | K49: 0 | L49: 50 | M49: 0 | N49: 40 | O49: 0
A50: Fountain Well No 4 Dale St | C50: Fountain Well No 4 Dale St NA | D50: 6 | E50: FSW-6 | F50: =VLOOKUP(A50,Type!$A$1:$C$132,3,0) -> CO0121300 | G50: =VLOOKUP(A50,Type!$A$1:$B$132,2,0) -> PWS and Other | H50: 38.688333 | I50: -104.705 | J50: 0 | K50: 10 | L50: 59 | M50: 0 | N50: 33 | O50: 46
A51: private well 809 Dale St. | B51: 42460 | C51: private well 809 Dale St. 2016-03-31 | D51: 36 | E51: FSW-36 | G51: =VLOOKUP(A51,Type!$A$1:$B$132,2,0) -> Private Well | H51: 38.6902 | I51: -104.7051 | J51: 0 | K51: 22 | L51: 110 | M51: 0 | N51: 56 | O51: 62
A52: private well 8920 1/2 Rusique | B52: 42619 | C52: private well 8920 1/2 Rusique 2016-09-06 | D52: 111 | E52: FSW-111 | G52: =VLOOKUP(A52,Type!$A$1:$B$132,2,0) -> Private Well | H52: 38.703333 | I52: -104.70639 | J52: 18 | K52: 12 | L52: 40 | M52: 0 | N52: 43 | O52: 29
A53: monitoring well COS Pond-MWE | B53: 42494 | C53: monitoring well COS Pond-MWE 2016-05-04 | D53: 13 | E53: FSW-13 | G53: =VLOOKUP(A53,Type!$A$1:$B$132,2,0) -> PWS and Other | H53: 38.794681 | I53: -104.70693 | J53: 240 | K53: 200 | L53: 970 | M53: 25 | N53: 200 | O53: 1600
A54: Fountain Valley School | B54: 42516 | C54: Fountain Valley School 2016-05-26 | D54: 89 | E54: FSW-89 | F54: =VLOOKUP(A54,Type!$A$1:$C$132,3,0) -> CO0121300 | G54: =VLOOKUP(A54,Type!$A$1:$B$132,2,0) -> PWS and Other | H54: 38.74355 | I54: -104.7078 | J54: 23 | K54: 12 | L54: 34 | M54: 4.5 | N54: 33 | O54: 64
A55: private well 8760 S. Hwy 85 | B55: 42460 | C55: private well 8760 S. Hwy 85 2016-03-31 | D55: 31 | E55: FSW-31 | G55: =VLOOKUP(A55,Type!$A$1:$B$132,2,0) -> Private Well | H55: 38.705017 | I55: -104.71 | J55: 0 | K55: 0 | L55: 0 | M55: 0 | N55: 0 | O55: 0
A56: monitoring well Airplane Crash #1 | B56: 42782 | C56: monitoring well Airplane Crash #1 2017-02-16 | D56: 126 | E56: FSW-126 | G56: =VLOOKUP(A56,Type!$A$1:$B$132,2,0) -> PWS and Other | H56: 38.735551 | I56: -104.71358 | J56: 20 | K56: 6 | L56: 49 | M56: 0 | N56: 30 | O56: 36
A57: El Paso Parks A1 WELL | B57: 42431 | C57: El Paso Parks A1 WELL 2016-03-02 | D57: 1 | E57: FSW-1 | F57: =VLOOKUP(A57,Type!$A$1:$C$132,3,0) -> CO0221435 | G57: =VLOOKUP(A57,Type!$A$1:$B$132,2,0) -> PWS and Other | H57: 38.709167 | I57: -104.71583 | J57: 28 | K57: 5.3 | L57: 38 | M57: 0 | N57: 18 | O57: 31
A58: El Paso Parks Mckinnon Well | B58: 42431 | C58: El Paso Parks Mckinnon Well 2016-03-02 | D58: 3 | E58: FSW-3 | F58: =VLOOKUP(A58,Type!$A$1:$C$132,3,0) -> CO0221436 | G58: =VLOOKUP(A58,Type!$A$1:$B$132,2,0) -> PWS and Other | H58: 38.709722 | I58: -104.71611 | J58: 260 | K58: 6.1 | L58: 35 | M58: 0 | N58: 15 | O58: 20
A59: El Paso Parks Fountain Creek Nature Ctr | B59: 42431 | C59: El Paso Parks Fountain Creek Nature Ctr 2016-03-02 | D59: 2 | E59: FSW-2 | F59: =VLOOKUP(A59,Type!$A$1:$C$132,3,0) -> CO0221436 | G59: =VLOOKUP(A59,Type!$A$1:$B$132,2,0) -> PWS and Other | H59: 38.713611 | I59: -104.71667 | J59: 0 | K59: 0 | L59: 0 | M59: 0 | N59: 0 | O59: 0
A60: private well 3815 Cresta Loma PL | B60: 42549 | C60: private well 3815 Cresta Loma PL 2016-06-28 | D60: 82 | E60: FSW-82 | G60: =VLOOKUP(A60,Type!$A$1:$B$132,2,0) -> Private Well | H60: 38.776783 | I60: -104.72427 | J60: 98 | K60: 62 | L60: 260 | M60: 0 | N60: 40 | O60: 180
A61: Security W8 Well | B61: 42417 | C61: Security W8 Well 2016-02-17 | D61: 63 | E61: FSW-63 | F61: =VLOOKUP(A61,Type!$A$1:$C$132,3,0) -> CO0121775 | G61: =VLOOKUP(A61,Type!$A$1:$B$132,2,0) -> PWS and Other | H61: 38.768495 | I61: -104.72443 | J61: 0 | K61: 50 | L61: 280 | M61: 0 | N61: 60 | O61: 560
...

Sheet Type
A1: Name_OR_Site | B1: Type | C1: PWS_ID | D1: Latitude | E1: Longitude | F1: Data_Source | G1: Confidential | H1: PFBS | I1: PFHpA | J1: PFHxS | K1: PFNA | L1: PFOA | M1: PFOS | N1: Date | O1: Sample_ID2 | P1: Sample_ID
A2: Wigwam Well CR #1 | B2: PWS and Other | C2: CO0121470 | D2: 38.541917 | E2: -104.64063 | F2: El Paso GW | G2: Yes | H2: 27 | I2: 7.5 | J2: 50 | K2: 0 | L2: 25 | M2: 18 | N2: 39595 | O2: Wigwam Well CR #1 2008-05-27 | P2: FSW-131
A3: Widefield Well W-2 | B3: PWS and Other | C3: CO0121900 | D3: 38.73605 | E3: -104.72901 | F3: El Paso GW | G3: Yes | H3: 36 | I3: 12 | J3: 65 | K3: 0 | L3: 20 | M3: 78 | N3: 42493 | O3: Widefield Well W-2 2016-05-03 | P3: FSW-75
A4: Widefield Well JHW2 | B4: PWS and Other | C4: CO0121900 | D4: 38.7298 | E4: -104.65357 | F4: El Paso GW | G4: Yes | H4: 0 | I4: 0 | J4: 0 | K4: 0 | L4: 4.7 | M4: 2.9 | N4: 42536 | O4: Widefield Well JHW2 2016-06-15 | P4: FSW-130
A5: Widefield Well E2 | B5: PWS and Other | C5: CO0121900 | D5: 38.724384 | E5: -104.72443 | F5: El Paso GW | G5: Yes | H5: 72 | I5: 22 | J5: 140 | K5: 3.8 | L5: 33 | M5: 260 | N5: 42682 | O5: Widefield Well E2 2016-11-08 | P5: FSW-74
A6: Widefield Well C36 | B6: PWS and Other | C6: CO0121900 | D6: 38.732413 | E6: -104.73176 | F6: El Paso GW | G6: Yes | H6: 83 | I6: 21 | J6: 350 | K6: 0 | L6: 39 | M6: 71 | N6: 42594 | O6: Widefield Well C36 2016-08-12 | P6: FSW-73
A7: Widefield Well C3 | B7: PWS and Other | C7: CO0121900 | D7: 38.729424 | E7: -104.729 | F7: El Paso GW | G7: Yes | H7: 56 | I7: 22 | J7: 260 | K7: 0 | L7: 42 | M7: 75 | N7: 42493 | O7: Widefield Well C3 2016-05-03 | P7: FSW-72
A8: Widefield Well C1 | B8: PWS and Other | C8: CO0121900 | D8: 38.729257 | E8: -104.72616 | F8: El Paso GW | G8: Yes | H8: 36 | I8: 13 | J8: 80 | K8: 0 | L8: 20 | M8: 93 | N8: 42493 | O8: Widefield Well C1 2016-05-03 | P8: FSW-71
A9: Widefield W7 Well | B9: PWS and Other | C9: CO0121900 | D9: 38.727847 | E9: -104.72465 | F9: El Paso GW | G9: Yes | H9: 71 | I9: 27 | J9: 150 | K9: 0 | L9: 35 | M9: 260 | N9: 42594 | O9: Widefield W7 Well 2016-08-12 | P9: FSW-70
A10: Widefield W4 Well | B10: PWS and Other | C10: CO0121900 | D10: 38.735448 | E10: -104.73184 | F10: El Paso GW | G10: Yes | H10: 0 | I10: 24 | J10: 330 | K10: 0 | L10: 45 | M10: 51 | N10: 41778 | O10: Widefield W4 Well 2014-05-19 | P10: FSW-92
A11: Widefield W3 Well | B11: PWS and Other | C11: CO0121900 | D11: 38.733889 | E11: -104.73083 | F11: El Paso GW | G11: Yes | H11: 64 | I11: 23 | J11: 320 | K11: 0 | L11: 48 | M11: 90 | N11: 42492 | O11: Widefield W3 Well 2016-05-02 | P11: FSW-69
A12: Widefield W1 Well | B12: PWS and Other | C12: CO0121900 | D12: 38.736887 | E12: -104.72973 | F12: El Paso GW | G12: Yes | H12: 0 | I12: 0 | J12: 0 | K12: 0 | L12: 26 | M12: 72 | N12: 42410 | O12: Widefield W1 Well 2016-02-10 | P12: FSW-68
A13: Widefield Jhw5R Well | B13: PWS and Other | C13: CO0121900 | D13: 38.730278 | E13: -104.65111 | F13: El Paso GW | G13: Yes | H13: 0 | I13: 0 | J13: 0 | K13: 0 | L13: 0 | M13: 0 | N13: 41778 | O13: Widefield Jhw5R Well 2014-05-19 | P13: FSW-90
... A49: Norad MHP 5775 Southmoor | B49: PWS and Other | C49: CO0121500 | D49: 38.748 | E49: -104.7428 | F49: El Paso GW | G49: Yes | H49: 230 | I49: 44 | J49: 740 | K49: 0 | L49: 63 | M49: 140 | N49: 42460 | O49: Norad MHP 5775 Southmoor 2016-03-31 | P49: FSW-91
A50: monitoring well TH22 #4 | B50: PWS and Other | D50: 38.779995 | E50: -104.76303 | F50: El Paso GW | G50: Yes | H50: 0 | I50: 0 | J50: 10 | K50: 0 | L50: 4 | M50: 18 | N50: 42781 | O50: monitoring well TH22 #4 2017-02-15 | P50: FSW-129
A51: monitoring well Rocky Mountain Materials | B51: PWS and Other | D51: 38.773766 | E51: -104.76486 | F51: El Paso GW | G51: Yes | H51: 9 | I51: 4 | J51: 13 | K51: 0 | L51: 8 | M51: 9 | N51: 42437 | O51: monitoring well Rocky Mountain Materials 2016-03-08 | P51: FSW-17
A52: monitoring well Recycle Center #3 | B52: PWS and Other | D52: 38.788328 | E52: -104.77747 | F52: El Paso GW | G52: Yes | H52: 15 | I52: 4 | J52: 15 | K52: 0 | L52: 9 | M52: 26 | N52: 42781 | O52: monitoring well Recycle Center #3 2017-02-15 | P52: FSW-128
A53: monitoring well nonpotable well GWMW | B53: PWS and Other | D53: 38.765701 | E53: -104.76093 | F53: El Paso GW | G53: Yes | H53: 110 | I53: 22 | J53: 410 | K53: 0 | L53: 38 | M53: 290 | N53: 42466 | O53: monitoring well nonpotable well GWMW 2016-04-06 | P53: FSW-16
A54: monitoring well MW-1 Kingz | B54: PWS and Other | D54: 38.787078 | E54: -104.75432 | F54: El Paso GW | G54: Yes | H54: 20 | I54: 12 | J54: 93 | K54: 0 | L54: 13 | M54: 41 | N54: 42494 | O54: monitoring well MW-1 Kingz 2016-05-04 | P54: FSW-15
A55: monitoring well Mars Gas #2 | B55: PWS and Other | D55: 38.777495 | E55: -104.77108 | F55: El Paso GW | G55: Yes | H55: 0 | I55: 2 | J55: 15 | K55: 0 | L55: 4 | M55: 28 | N55: 42781 | O55: monitoring well Mars Gas #2 2017-02-15 | P55: FSW-127
A56: monitoring well HMW-63 Schlage | B56: PWS and Other | D56: 38.778542 | E56: -104.73804 | F56: El Paso GW | G56: Yes | H56: 21 | I56: 0 | J56: 6.9 | K56: 0 | L56: 0 | M56: 0 | N56: 42494 | O56: monitoring well HMW-63 Schlage 2016-05-04 | P56: FSW-14
A57: monitoring well COS Pond-MWE | B57: PWS and Other | D57: 38.794681 | E57: -104.70693 | F57: El Paso GW | G57: Yes | H57: 240 | I57: 200 | J57: 970 | K57: 25 | L57: 200 | M57: 1600 | N57: 42494 | O57: monitoring well COS Pond-MWE 2016-05-04 | P57: FSW-13
A58: monitoring well Airplane Crash #1 | B58: PWS and Other | D58: 38.735551 | E58: -104.71358 | F58: El Paso GW | G58: Yes | H58: 20 | I58: 6 | J58: 49 | K58: 0 | L58: 30 | M58: 36 | N58: 42782 | O58: monitoring well Airplane Crash #1 2017-02-16 | P58: FSW-126
A59: Garden Valley No 8 Well | B59: PWS and Other | C59: CO0121325 | D59: 38.79615 | E59: -104.79104 | F59: El Paso GW | G59: Yes | H59: 0 | I59: 0 | J59: 0 | K59: 0 | L59: 0 | M59: 0 | N59: 42423 | O59: Garden Valley No 8 Well 2016-02-23 | P59: FSW-12
A60: Garden Valley 5908 | B60: PWS and Other | C60: CO0121325 | D60: 38.79748 | E60: -104.79417 | F60: El Paso GW | G60: Yes | H60: 48 | I60: 5.5 | J60: 20 | K60: 5.4 | L60: 13 | M60: 34 | N60: 42507 | O60: Garden Valley 5908 2016-05-17 | P60: FSW-11
A61: Garden Valley 5360 | B61: PWS and Other | C61: CO0121325 | D61: 38.797222 | E61: -104.79426 | F61: El Paso GW | G61: Yes | H61: 46 | I61: 4.9 | J61: 19 | K61: 6.4 | L61: 11 | M61: 37 | N61: 42507 | O61: Garden Valley 5360 2016-05-17 | P61: FSW-10
A62: Garden Valley 5359 | B62: PWS and Other | C62: CO0121325 | D62: 38.796944 | E62: -104.79417 | F62: El Paso GW | G62: Yes | H62: 49 | I62: 8 | J62: 20 | K62: 6.6 | L62: 20 | M62: 36 | N62: 42507 | O62: Garden Valley 5359 2016-05-17 | P62: FSW-9
A63: Garden Valley 5356 | B63: PWS and Other | C63: CO0121325 | D63: 38.796389 | E63: -104.7937 | F63: El Paso GW | G63: Yes | H63: 46 | I63: 5.7 | J63: 19 | K63: 5.5 | L63: 13 | M63: 37 | N63: 42507 | O63: Garden Valley 5356 2016-05-17 | P63: FSW-8
A64: FV Shopping Center No 1 Well | B64: PWS and Other | C64: CO0221440 | D64: 38.751666 | E64: -104.74528 | F64: El Paso GW | G64: Yes | H64: 150 | I64: 42 | J64: 510 | K64: 5.6 | L64: 73 | M64: 140 | N64: 42507 | O64: FV Shopping Center No 1 Well 2016-05-17 | P64: FSW-7
A65: Fountain Well No 4 Dale St | B65: PWS and Other | C65: CO0121300 | D65: 38.688333 | E65: -104.705 | F65: El Paso GW | G65: Yes | H65: 0 | I65: 10 | J65: 59 | K65: 0 | L65: 33 | M65: 46 | O65: Fountain Well No 4 Dale St NA | P65: FSW-6
A66: Fountain Well No 3 Shop Well | B66: PWS and Other | C66: CO0121300 | D66: 38.681945 | E66: -104.69972 | F66: El Paso GW | G66: Yes | H66: 0 | I66: 0 | J66: 50 | K66: 0 | L66: 27 | M66: 50 | O66: Fountain Well No 3 Shop Well NA | P66: FSW-5
A67: Fountain Well No 2 South Park Well | B67: PWS and Other | C67: CO0121300 | D67: 38.685555 | E67: -104.70278 | F67: El Paso GW | G67: Yes | H67: 0 | I67: 10 | J67: 54 | K67: 0 | L67: 32 | M67: 49 | O67: Fountain Well No 2 South Park Well NA | P67: FSW-4
A68: Fountain Well No 1 North Park Well | B68: PWS and Other | C68: CO0121300 | D68: 38.686679 | E68: -104.70371 | F68: El Paso GW | G68: Yes | H68: 0 | I68: 0 | J68: 50 | K68: 0 | L68: 40 | M68: 0 | N68: 41472 | O68: Fountain Well No 1 North Park Well 2013-07-17 | P68: FSW-93
A69: Fountain Valley School | B69: PWS and Other | C69: CO0121300 | D69: 38.74355 | E69: -104.7078 | F69: El Paso GW | G69: Yes | H69: 23 | I69: 12 | J69: 34 | K69: 4.5 | L69: 33 | M69: 64 | N69: 42516 | O69: Fountain Valley School 2016-05-26 | P69: FSW-89
A70: Fountain Faith Fellowship | B70: PWS and Other | C70: CO0121300 | D70: 38.659137 | E70: -104.69044 | F70: El Paso GW | G70: Yes | H70: 0 | I70: 3.8 | J70: 10 | K70: 0 | L70: 9.1 | M70: 0 | N70: 42548 | O70: Fountain Faith Fellowship 2016-06-27 | P70: FSW-77
A71: First United Pentacostal Church | B71: PWS and Other | C71: CO0221276 | D71: 38.7696 | E71: -104.75488 | F71: El Paso GW | G71: Yes | H71: 90 | I71: 20 | J71: 210 | K71: 3.9 | L71: 30 | M71: 130 | N71: 42507 | O71: First United Pentacostal Church 2016-05-17 | P71: FSW-18
A72: El Paso Parks Mckinnon Well | B72: PWS and Other | C72: CO0221436 | D72: 38.709722 | E72: -104.71611 | F72: El Paso GW | G72: Yes | H72: 260 | I72: 6.1 | J72: 35 | K72: 0 | L72: 15 | M72: 20 | N72: 42431 | O72: El Paso Parks Mckinnon Well 2016-03-02 | P72: FSW-3
A73: El Paso Parks Fountain Creek Nature Ctr | B73: PWS and Other | C73: CO0221436 | D73: 38.713611 | E73: -104.71667 | F73: El Paso GW | G73: Yes | H73: 0 | I73: 0 | J73: 0 | K73: 0 | L73: 0 | M73: 0 | N73: 42431 | O73: El Paso Parks Fountain Creek Nature Ctr 2016-03-02 | P73: FSW-2
A74: El Paso Parks A1 WELL | B74: PWS and Other | C74: CO0221435 | D74: 38.709167 | E74: -104.71583 | F74: El Paso GW | G74: Yes | H74: 28 | I74: 5.3 | J74: 38 | K74: 0 | L74: 18 | M74: 31 | N74: 42431 | O74: El Paso Parks A1 WELL 2016-03-02 | P74: FSW-1
A75: CO. Centre Metro district | B75: PWS and Other | C75: CO0121140 | D75: 38.768417 | E75: -104.64929 | F75: El Paso GW | G75: Yes | H75: 0 | I75: 0 | J75: 0 | K75: 0 | L75: 0 | M75: 0 | N75: 42548 | O75: CO. Centre Metro district 2016-06-27 | P75: FSW-88
...

Sheet Sheet1
A1: GIS_name
A2: Wigwam Well CR #1
A3: Widefield Well W-2
A4: Widefield Well JHW2
A5: Widefield Well E2
A6: Widefield Well C36
A7: Widefield Well C3
A8: Widefield Well C1
A9: Widefield W7 Well
A10: Widefield W4 Well
A11: Widefield W3 Well
A12: Widefield W1 Well
... A66: CO. Centre Metro district
